#VRML_SIM R2019a utf8
WorldInfo {
}
Viewpoint {
  orientation -0.9216544408540646 -0.38079828981714814 -0.07446982023824643 0.4181703203052755
  position 0.4941368212258809 2.995649142276174 4.548985993372637
}
TexturedBackground {
}
TexturedBackgroundLight {
}
Floor {
}
DEF S_Mill Solid {
  translation -0.010000000000000009 0.025 0
  children [
    DEF Group Group {
      children [
        DEF S_TOP Shape {
          appearance DEF APP_GREEN PBRAppearance {
            baseColor 0.5411764705882353 0.8862745098039215 0.20392156862745098
          }
          geometry DEF G_TOP Box {
            size 1 0.05 1
          }
        }
        DEF T_TOP Transform {
          translation 0 0.95 0
          rotation 1 0 0 0
          children [
            Shape {
              appearance USE APP_GREEN
              geometry USE G_TOP
            }
          ]
        }
        DEF GROUP_FACE(1) Group {
          children [
            Transform {
              translation 0.5 0.475 0.45
              children [
                Shape {
                  appearance DEF APP_BLUE PBRAppearance {
                    baseColor 0.12549019607843137 0.2901960784313726 0.5294117647058824
                  }
                  geometry DEF G_BOX Box {
                    size 0.01 0.9 0.1
                  }
                }
                Transform {
                  translation 0 0 -0.9
                  children [
                    Shape {
                      appearance USE APP_BLUE
                      geometry USE G_BOX
                    }
                  ]
                }
                Transform {
                  translation 0 0.4 -0.45
                  rotation 1 0 0 1.57
                  children [
                    Shape {
                      appearance USE APP_BLUE
                      geometry USE G_BOX
                    }
                  ]
                }
                Transform {
                  translation 0 -0.4 -0.45
                  rotation 1 0 0 1.57
                  children [
                    Shape {
                      appearance USE APP_BLUE
                      geometry USE G_BOX
                    }
                  ]
                }
                Transform {
                  translation 0 0 -0.45
                  rotation 1 0 0 0.85
                  children [
                    Shape {
                      appearance USE APP_BLUE
                      geometry DEF G_3FACE_1 Box {
                        size 0.01 1.0999999999999999 0.07
                      }
                    }
                  ]
                }
                Transform {
                  translation 0 0 -0.45
                  rotation 1 0 0 -0.85
                  children [
                    Shape {
                      appearance USE APP_BLUE
                      geometry USE G_3FACE_1
                    }
                  ]
                }
              ]
            }
            DEF GROUP_FACE(1) Group {
              children [
                Transform {
                  translation -0.5 0.475 0.45
                  children [
                    Shape {
                      appearance USE APP_BLUE
                      geometry USE G_BOX
                    }
                    Transform {
                      translation 0 0 -0.9
                      children [
                        Shape {
                          appearance USE APP_BLUE
                          geometry USE G_BOX
                        }
                      ]
                    }
                    Transform {
                      translation 0 0.4 -0.45
                      rotation 1 0 0 1.57
                      children [
                        Shape {
                          appearance USE APP_BLUE
                          geometry USE G_BOX
                        }
                      ]
                    }
                    Transform {
                      translation 0 -0.4 -0.45
                      rotation 1 0 0 1.57
                      children [
                        Shape {
                          appearance USE APP_BLUE
                          geometry USE G_BOX
                        }
                      ]
                    }
                    Transform {
                      translation 0 0 -0.45
                      rotation 1 0 0 0.85
                      children [
                        Shape {
                          appearance USE APP_BLUE
                          geometry USE G_3FACE_1
                        }
                      ]
                    }
                    Transform {
                      translation 0 0 -0.45
                      rotation 1 0 0 -0.85
                      children [
                        Shape {
                          appearance USE APP_BLUE
                          geometry USE G_3FACE_1
                        }
                      ]
                    }
                  ]
                }
              ]
            }
          ]
        }
        DEF GROUP_FACE(2) Group {
          children [
            Transform {
              translation 0.44 0.475 0.495
              children [
                Shape {
                  appearance DEF APP_GREY PBRAppearance {
                    baseColor 0.5333333333333333 0.5411764705882353 0.5215686274509804
                  }
                  geometry DEF G_FACE(2) Box {
                    size 0.1 0.9 0.01
                  }
                }
                Transform {
                  translation -0.88 0 0
                  children [
                    Shape {
                      appearance USE APP_GREY
                      geometry USE G_FACE(2)
                    }
                  ]
                }
                Transform {
                  translation -0.44 0.4 0
                  rotation 0 0 1 1.57
                  children [
                    Shape {
                      appearance USE APP_GREY
                      geometry USE G_FACE(2)
                    }
                  ]
                }
                Transform {
                  translation -0.44 -0.4 0
                  rotation 0 0 1 1.57
                  children [
                    Shape {
                      appearance USE APP_GREY
                      geometry USE G_FACE(2)
                    }
                  ]
                }
                Transform {
                  translation -0.44 0 0
                  rotation 0 0 1 0.85
                  children [
                    Shape {
                      appearance USE APP_GREY
                      geometry DEF G_4FACE_1 Box {
                        size 0.07 1.05 0.01
                      }
                    }
                  ]
                }
                Transform {
                  translation -0.44 0 0
                  rotation 0 0 1 -0.85
                  children [
                    Shape {
                      appearance USE APP_GREY
                      geometry USE G_4FACE_1
                    }
                  ]
                }
              ]
            }
            DEF GROUP_FACE(2) Group {
              children [
                Transform {
                  translation 0.44 0.475 -0.495
                  children [
                    Shape {
                      appearance USE APP_GREY
                      geometry USE G_FACE(2)
                    }
                    Transform {
                      translation -0.88 0 0
                      children [
                        Shape {
                          appearance USE APP_GREY
                          geometry USE G_FACE(2)
                        }
                      ]
                    }
                    Transform {
                      translation -0.44 0.4 0
                      rotation 0 0 1 1.57
                      children [
                        Shape {
                          appearance USE APP_GREY
                          geometry USE G_FACE(2)
                        }
                      ]
                    }
                    Transform {
                      translation -0.44 -0.4 0
                      rotation 0 0 1 1.57
                      children [
                        Shape {
                          appearance USE APP_GREY
                          geometry USE G_FACE(2)
                        }
                      ]
                    }
                    Transform {
                      translation -0.44 0 0
                      rotation 0 0 1 0.85
                      children [
                        Shape {
                          appearance USE APP_GREY
                          geometry USE G_4FACE_1
                        }
                      ]
                    }
                    Transform {
                      translation -0.44 0 0
                      rotation 0 0 1 0.85
                      children [
                        Shape {
                          appearance USE APP_GREY
                          geometry USE G_4FACE_1
                        }
                      ]
                    }
                  ]
                }
              ]
            }
          ]
        }
        DEF G_FINAL Group {
          children [
            Transform {
              translation 0 1.225 0
              children [
                Shape {
                  appearance PBRAppearance {
                    baseColor 0 0 0
                  }
                  geometry DEF G_BOXMILL Box {
                    size 0.1 0.4 0.1
                  }
                }
                HingeJoint {
                  jointParameters HingeJointParameters {
                    axis 0 1 0
                    anchor 0 0.2 0
                    staticFriction 0.02
                  }
                  endPoint Solid {
                    translation 0.35 0.22 0
                    children [
                      Shape {
                        appearance DEF APP_Y PBRAppearance {
                          baseColor 0.9882352941176471 0.9137254901960784 0.30980392156862746
                        }
                        geometry DEF G_B Box {
                          size 0.8 0.05 0.06
                        }
                      }
                      HingeJoint {
                        jointParameters HingeJointParameters {
                          anchor 0.35 0 0
                          staticFriction 0.01
                        }
                        endPoint Solid {
                          translation 0.3550000000625196 -3.9202189960896305e-06 0
                          rotation 1 0 0 0
                          children [
                            DEF GROUP Group {
                              children [
                                Shape {
                                  appearance DEF APP_Y PBRAppearance {
                                    baseColor 0.9607843137254902 0.4745098039215686 0
                                  }
                                  geometry DEF G_MILL Box {
                                    size 0.01 0.5 0.05
                                  }
                                }
                                Transform {
                                  rotation 1 0 0 1.57
                                  children [
                                    Shape {
                                      appearance USE APP_Y
                                      geometry USE G_MILL
                                    }
                                  ]
                                }
                              ]
                            }
                          ]
                          physics Physics {
                          }
                        }
                      }
                    ]
                    boundingObject USE G_B
                    physics Physics {
                    }
                  }
                }
              ]
            }
          ]
        }
      ]
    }
  ]
  name "solid(4)"
}
